Workbook

Sheet Sheet1
A1: OrderID | B1: CustomerName | C1: Region | D1: Product | E1: Quantity | F1: UnitPrice | G1: OrderDate | H1: Question No:4 | I1: Total sales Question No:5 | J1: Question No:6
A2: 1001 | B2: Amit Sharma | C2: North | D2: Notebook | E2: 10 | F2: 50 | G2: 45413 | H2: =COUNTA(B2:B51) -> 50 | I2: =$E2*$F2 -> 500 | J2: =SUMIFS($I$2:$I$63,$D$2:$D$63,"Notebook",$C$2:$C$63,"North") -> 2900
A3: 1002 | B3: Neha Verma | C3: South | D3: Pen | E3: 20 | F3: 10 | G3: 45444 | I3: =$E3*$F3 -> 200 | J3: =SUMIFS(I3:I52,D3:D52,"NOTEBOOK",C3:C52,"NORTH") -> 2400
A4: 1003 | B4: Rahul Singh | C4: East | D4: Marker | E4: 15 | F4: 25 | G4: 45474 | I4: =$E4*$F4 -> 375 | J4: =SUMIFS(I4:I53,D4:D53,"NOTEBOOK",C4:C53,"NORTH") -> 2400
A5: 1004 | B5: Pooja Mehta | C5: West | D5: Notebook | E5: 5 | F5: 50 | G5: 45505 | I5: =$E5*$F5 -> 250 | J5: =SUMIFS(I5:I54,D5:D54,"NOTEBOOK",C5:C54,"NORTH") -> 2400
A6: 1005 | B6: Ankit Jain | C6: North | D6: Pencil | E6: 30 | F6: 5 | G6: 45566 | I6: =$E6*$F6 -> 150 | J6: =SUMIFS(I6:I55,D6:D55,"NOTEBOOK",C6:C55,"NORTH") -> 2400
A7: 1006 | B7: Sneha Patel | C7: South | D7: Notebook | E7: 12 | F7: 50 | G7: 45597 | I7: =$E7*$F7 -> 600 | J7: =SUMIFS(I7:I56,D7:D56,"NOTEBOOK",C7:C56,"NORTH") -> 2400
A8: 1007 | B8: Vikas Gupta | C8: East | D8: Eraser | E8: 25 | F8: 8 | G8: 13-01-2024 | I8: =$E8*$F8 -> 200 | J8: =SUMIFS(I8:I57,D8:D57,"NOTEBOOK",C8:C57,"NORTH") -> 2400
A9: 1008 | B9: Meera Nair | C9: West | D9: Pen | E9: 18 | F9: 10 | G9: 15-01-2024 | I9: =$E9*$F9 -> 180 | J9: =SUMIFS(I9:I58,D9:D58,"NOTEBOOK",C9:C58,"NORTH") -> 2400
A10: 1009 | B10: Anjali Rao | C10: North | D10: Marker | E10: 22 | F10: 25 | G10: 17-01-2024 | I10: =$E10*$F10 -> 550 | J10: =SUMIFS(I10:I59,D10:D59,"NOTEBOOK",C10:C59,"NORTH") -> 2400
A11: 1010 | B11: Manoj Das | C11: South | D11: Notebook | E11: 8 | F11: 50 | G11: 18-01-2024 | I11: =$E11*$F11 -> 400 | J11: =SUMIFS(I11:I60,D11:D60,"NOTEBOOK",C11:C60,"NORTH") -> 2400
A12: 1011 | B12: Ritika Sen | C12: East | D12: Pencil | E12: 40 | F12: 5 | G12: 19-01-2024 | I12: =$E12*$F12 -> 200 | J12: =SUMIFS(I12:I61,D12:D61,"NOTEBOOK",C12:C61,"NORTH") -> 2400
A13: 1012 | B13: Karan Malhotra | C13: West | D13: Eraser | E13: 35 | F13: 8 | G13: 20-01-2024 | I13: =$E13*$F13 -> 280 | J13: =SUMIFS(I13:I62,D13:D62,"NOTEBOOK",C13:C62,"NORTH") -> 2400
A14: 1013 | B14: Aryan Joshi | C14: North | D14: Notebook | E14: 14 | F14: 50 | G14: 22-01-2024 | I14: =$E14*$F14 -> 700 | J14: =SUMIFS($I$14:$I$63,$D$14:$D$63,"Notebook",$C$14:$C$63,"North") -> 2400
A15: 1014 | B15: Divya Kapoor | C15: South | D15: Pen | E15: 28 | F15: 10 | G15: 23-01-2024 | I15: =$E15*$F15 -> 280 | J15: =SUMIFS(I15:I64,D15:D64,"NOTEBOOK",C15:C64,"NORTH") -> 1700
A16: 1015 | B16: Sahil Arora | C16: East | D16: Marker | E16: 12 | F16: 25 | G16: 24-01-2024 | I16: =$E16*$F16 -> 300 | J16: =SUMIFS(I16:I65,D16:D65,"NOTEBOOK",C16:C65,"NORTH") -> 1700
A17: 1016 | B17: Muskan Jain | C17: West | D17: Pencil | E17: 25 | F17: 5 | G17: 26-01-2024 | I17: =$E17*$F17 -> 125 | J17: =SUMIFS(I17:I66,D17:D66,"NOTEBOOK",C17:C66,"NORTH") -> 1700
A18: 1017 | B18: Rohan Gupta | C18: North | D18: Eraser | E18: 20 | F18: 8 | G18: 28-01-2024 | I18: =$E18*$F18 -> 160 | J18: =SUMIFS(I18:I67,D18:D67,"NOTEBOOK",C18:C67,"NORTH") -> 1700
A19: 1018 | B19: Nidhi Sharma | C19: South | D19: Notebook | E19: 10 | F19: 50 | G19: 29-01-2024 | I19: =$E19*$F19 -> 500 | J19: =SUMIFS(I19:I68,D19:D68,"NOTEBOOK",C19:C68,"NORTH") -> 1700
A20: 1019 | B20: Tarun Verma | C20: East | D20: Pen | E20: 15 | F20: 10 | G20: 30-01-2024 | I20: =$E20*$F20 -> 150 | J20: =SUMIFS(I20:I69,D20:D69,"NOTEBOOK",C20:C69,"NORTH") -> 1700
A21: 1020 | B21: Simran Kaur | C21: West | D21: Marker | E21: 18 | F21: 25 | G21: 45293 | I21: =$E21*$F21 -> 450 | J21: =SUMIFS(I21:I70,D21:D70,"NOTEBOOK",C21:C70,"NORTH") -> 1700
A22: 1021 | B22: Deepak Rao | C22: North | D22: Notebook | E22: 9 | F22: 50 | G22: 45324 | I22: =$E22*$F22 -> 450 | J22: =SUMIFS(I22:I71,D22:D71,"NOTEBOOK",C22:C71,"NORTH") -> 1700
A23: 1022 | B23: Payal Mehta | C23: South | D23: Pencil | E23: 35 | F23: 5 | G23: 45353 | I23: =$E23*$F23 -> 175 | J23: =SUMIFS(I23:I72,D23:D72,"NOTEBOOK",C23:C72,"NORTH") -> 1250
A24: 1023 | B24: Aditya Singh | C24: East | D24: Eraser | E24: 30 | F24: 8 | G24: 45384 | I24: =$E24*$F24 -> 240 | J24: =SUMIFS(I24:I73,D24:D73,"NOTEBOOK",C24:C73,"NORTH") -> 1250
A25: 1024 | B25: Shreya Nair | C25: West | D25: Notebook | E25: 11 | F25: 50 | G25: 45445 | I25: =$E25*$F25 -> 550 | J25: =SUMIFS(I25:I74,D25:D74,"NOTEBOOK",C25:C74,"NORTH") -> 1250
A26: 1025 | B26: Sanjay Kumar | C26: North | D26: Pen | E26: 14 | F26: 10 | G26: 45475 | I26: =$E26*$F26 -> 140 | J26: =SUMIFS(I26:I75,D26:D75,"NOTEBOOK",C26:C75,"NORTH") -> 1250
A27: 1026 | B27: Aarti Sharma | C27: South | D27: Marker | E27: 16 | F27: 25 | G27: 45506 | I27: =$E27*$F27 -> 400 | J27: =SUMIFS(I27:I76,D27:D76,"NOTEBOOK",C27:C76,"NORTH") -> 1250
A28: 1027 | B28: Rajesh Patel | C28: East | D28: Pencil | E28: 22 | F28: 5 | G28: 45537 | I28: =$E28*$F28 -> 110 | J28: =SUMIFS(I28:I77,D28:D77,"NOTEBOOK",C28:C77,"NORTH") -> 1250
A29: 1028 | B29: Preeti Joshi | C29: West | D29: Eraser | E29: 27 | F29: 8 | G29: 45567 | I29: =$E29*$F29 -> 216 | J29: =SUMIFS(I29:I78,D29:D78,"NOTEBOOK",C29:C78,"NORTH") -> 1250
A30: 1029 | B30: Anurag Mishra | C30: North | D30: Notebook | E30: 13 | F30: 50 | G30: 45628 | I30: =$E30*$F30 -> 650 | J30: =SUMIFS(I30:I79,D30:D79,"NOTEBOOK",C30:C79,"NORTH") -> 1250
A31: 1030 | B31: Sanya Kapoor | C31: South | D31: Pen | E31: 32 | F31: 10 | G31: 13-02-2024 | I31: =$E31*$F31 -> 320 | J31: =SUMIFS(I31:I80,D31:D80,"NOTEBOOK",C31:C80,"NORTH") -> 600
A32: 1031 | B32: Harsh Yadav | C32: East | D32: Marker | E32: 10 | F32: 25 | G32: 14-02-2024 | I32: =$E32*$F32 -> 250 | J32: =SUMIFS(I32:I81,D32:D81,"NOTEBOOK",C32:C81,"NORTH") -> 600
A33: 1032 | B33: Kajal Rani | C33: West | D33: Pencil | E33: 18 | F33: 5 | G33: 16-02-2024 | I33: =$E33*$F33 -> 90 | J33: =SUMIFS(I33:I82,D33:D82,"NOTEBOOK",C33:C82,"NORTH") -> 600
A34: 1033 | B34: Varun Sharma | C34: North | D34: Eraser | E34: 22 | F34: 8 | G34: 17-02-2024 | I34: =$E34*$F34 -> 176 | J34: =SUMIFS(I34:I83,D34:D83,"NOTEBOOK",C34:C83,"NORTH") -> 600
A35: 1034 | B35: Swati Arora | C35: South | D35: Notebook | E35: 17 | F35: 50 | G35: 18-02-2024 | I35: =$E35*$F35 -> 850 | J35: =SUMIFS(I35:I84,D35:D84,"NOTEBOOK",C35:C84,"NORTH") -> 600
A36: 1035 | B36: Akhil Jain | C36: East | D36: Pen | E36: 19 | F36: 10 | G36: 19-02-2024 | I36: =$E36*$F36 -> 190 | J36: =SUMIFS(I36:I85,D36:D85,"NOTEBOOK",C36:C85,"NORTH") -> 600
A37: 1036 | B37: Priyanka Das | C37: West | D37: Marker | E37: 15 | F37: 25 | G37: 21-02-2024 | I37: =$E37*$F37 -> 375 | J37: =SUMIFS(I37:I86,D37:D86,"NOTEBOOK",C37:C86,"NORTH") -> 600
A38: 1037 | B38: Ravi Nair | C38: North | D38: Pencil | E38: 28 | F38: 5 | G38: 22-02-2024 | I38: =$E38*$F38 -> 140 | J38: =SUMIFS(I38:I87,D38:D87,"NOTEBOOK",C38:C87,"NORTH") -> 600
A39: 1038 | B39: Komal Singh | C39: South | D39: Eraser | E39: 24 | F39: 8 | G39: 23-02-2024 | I39: =$E39*$F39 -> 192 | J39: =SUMIFS(I39:I88,D39:D88,"NOTEBOOK",C39:C88,"NORTH") -> 600
A40: 1039 | B40: Ayesha Khan | C40: East | D40: Notebook | E40: 16 | F40: 50 | G40: 25-02-2024 | I40: =$E40*$F40 -> 800 | J40: =SUMIFS(I40:I89,D40:D89,"NOTEBOOK",C40:C89,"NORTH") -> 600
...

Sheet Ans
A1: Total sales
A2: =SUM(Sheet1!E2*Sheet1!F2) -> 500
A3: =SUM(Sheet1!E3*Sheet1!F3) -> 200
A4: =SUM(Sheet1!E4*Sheet1!F4) -> 375
A5: =SUM(Sheet1!E5*Sheet1!F5) -> 250
A6: =SUM(Sheet1!E6*Sheet1!F6) -> 150
A7: =SUM(Sheet1!E7*Sheet1!F7) -> 600
A8: =SUM(Sheet1!E8*Sheet1!F8) -> 200
A9: =SUM(Sheet1!E9*Sheet1!F9) -> 180
A10: =SUM(Sheet1!E10*Sheet1!F10) -> 550
A11: =SUM(Sheet1!E11*Sheet1!F11) -> 400
A12: =SUM(Sheet1!E12*Sheet1!F12) -> 200
A13: =SUM(Sheet1!E13*Sheet1!F13) -> 280
... A50: =SUM(Sheet1!E50*Sheet1!F50) -> 600
